{
   "active_lock_reason" : null,
   "assignee" : null,
   "assignees" : [],
   "author_association" : "MEMBER",
   "body" : "Having an intermittent error in my local Windows:\r\n```\r\n> py -3 test\\functional\\test_runner.py --jobs 40 --timeout-factor=8\r\n...\r\n165/269 - feature_versionbits_warning.py failed, Duration: 59 s\r\n\r\n\r\nstdout:\r\n2023-09-25T11:29:08.904000Z TestFramework (INFO): PRNG seed is: 6135880998339750841\r\n2023-09-25T11:29:09.019000Z TestFramework (INFO): Initializing test directory C:\\Users\\hebasto\\AppData\\Local\\Temp\\test_runner_â¿_ð_20230925_122333\\feature_versionbits_warning_108\r\n2023-09-25T11:29:25.118000Z TestFramework (INFO): Check that there is no warning if previous VB_BLOCKS have <VB_THRESHOLD blocks with unknown versionbits version.\r\n2023-09-25T11:29:43.242000Z TestFramework (INFO): Check that there is a warning if previous VB_BLOCKS have >=VB_THRESHOLD blocks with unknown versionbits version.\r\n2023-09-25T11:29:50.044000Z TestFramework.p2p (WARNING): Connection lost to 127.0.0.1:12296 due to [WinError 10054] An existing connection was forcibly closed by the remote host\r\n2023-09-25T11:30:05.174000Z TestFramework (INFO): Stopping nodes\r\n2023-09-25T11:30:05.548000Z TestFramework (INFO): Cleaning up C:\\Users\\hebasto\\AppData\\Local\\Temp\\test_runner_â¿_ð_20230925_122333\\feature_versionbits_warning_108 on exit\r\n2023-09-25T11:30:05.548000Z TestFramework (INFO): Tests successful\r\n\r\n\r\nstderr:\r\nTraceback (most recent call last):\r\n  File \"C:\\Users\\hebasto\\bitcoin/test/functional/feature_versionbits_warning.py\", line 103, in <module>\r\n    VersionBitsWarningTest().main()\r\n  File \"C:\\Users\\hebasto\\bitcoin\\test\\functional\\test_framework\\test_framework.py\", line 154, in main\r\n    exit_code = self.shutdown()\r\n                ^^^^^^^^^^^^^^^\r\n  File \"C:\\Users\\hebasto\\bitcoin\\test\\functional\\test_framework\\test_framework.py\", line 361, in shutdown\r\n    shutil.rmtree(self.options.tmpdir)\r\n  File \"C:\\Python311\\Lib\\shutil.py\", line 759, in rmtree\r\n    return _rmtree_unsafe(path, onerror)\r\n    ^^^^^^^^^^^^^^^^^^^^^^^^^^^^^\r\nFile \"C:\\Python311\\Lib\\shutil.py\", line 617, in _rmtree_unsafe\r\n    _rmtree_unsafe(fullname, onerror)\r\nFile \"C:\\Python311\\Lib\\shutil.py\", line 617, in _rmtree_unsafe\r\n    _rmtree_unsafe(fullname, onerror)\r\nFile \"C:\\Python311\\Lib\\shutil.py\", line 622, in _rmtree_unsafe\r\n    onerror(os.unlink, fullname, sys.exc_info())\r\nFile \"C:\\Python311\\Lib\\shutil.py\", line 620, in _rmtree_unsafe\r\n    os.unlink(fullname)\r\nPermissionError: [WinError 32] The process cannot access the file because it is being used by another process: 'C:\\\\Users\\\\hebasto\\\\AppData\\\\Local\\\\Temp\\\\test_runner_â¿_ð_20230925_122333\\\\feature_versionbits_warning_108\\\\node0\\\\regtest\\\\debug.log'\r\n\r\n\r\n166/269 - feature_startupnotify.py passed, Duration: 30 s\r\n...\r\n```",
   "closed_at" : null,
   "closed_by" : null,
   "comments" : 1,
   "comments_url" : "https://api.github.com/repos/bitcoin/bitcoin/issues/28529/comments",
   "created_at" : "2023-09-25T12:18:39Z",
   "events_url" : "https://api.github.com/repos/bitcoin/bitcoin/issues/28529/events",
   "html_url" : "https://github.com/bitcoin/bitcoin/issues/28529",
   "id" : 1911379442,
   "labels" : [
      {
         "color" : "884400",
         "default" : false,
         "description" : null,
         "id" : 234877,
         "name" : "Windows",
         "node_id" : "MDU6TGFiZWwyMzQ4Nzc=",
         "url" : "https://api.github.com/repos/bitcoin/bitcoin/labels/Windows"
      },
      {
         "color" : "d4c5f9",
         "default" : false,
         "description" : null,
         "id" : 62963516,
         "name" : "Tests",
         "node_id" : "MDU6TGFiZWw2Mjk2MzUxNg==",
         "url" : "https://api.github.com/repos/bitcoin/bitcoin/labels/Tests"
      }
   ],
   "labels_url" : "https://api.github.com/repos/bitcoin/bitcoin/issues/28529/labels{/name}",
   "locked" : false,
   "milestone" : null,
   "node_id" : "I_kwDOABII585x7VXy",
   "number" : 28529,
   "performed_via_github_app" : null,
   "reactions" : {
      "+1" : 0,
      "-1" : 0,
      "confused" : 0,
      "eyes" : 0,
      "heart" : 0,
      "hooray" : 0,
      "laugh" : 0,
      "rocket" : 0,
      "total_count" : 0,
      "url" : "https://api.github.com/repos/bitcoin/bitcoin/issues/28529/reactions"
   },
   "repository_url" : "https://api.github.com/repos/bitcoin/bitcoin",
   "state" : "open",
   "state_reason" : null,
   "timeline_url" : "https://api.github.com/repos/bitcoin/bitcoin/issues/28529/timeline",
   "title" : "qa: No access to `debug.log` in functional tests on Windows",
   "updated_at" : "2023-09-25T12:24:08Z",
   "url" : "https://api.github.com/repos/bitcoin/bitcoin/issues/28529",
   "user" : {
      "avatar_url" : "https://avatars.githubusercontent.com/u/32963518?v=4",
      "events_url" : "https://api.github.com/users/hebasto/events{/privacy}",
      "followers_url" : "https://api.github.com/users/hebasto/followers",
      "following_url" : "https://api.github.com/users/hebasto/following{/other_user}",
      "gists_url" : "https://api.github.com/users/hebasto/gists{/gist_id}",
      "gravatar_id" : "",
      "html_url" : "https://github.com/hebasto",
      "id" : 32963518,
      "login" : "hebasto",
      "node_id" : "MDQ6VXNlcjMyOTYzNTE4",
      "organizations_url" : "https://api.github.com/users/hebasto/orgs",
      "received_events_url" : "https://api.github.com/users/hebasto/received_events",
      "repos_url" : "https://api.github.com/users/hebasto/repos",
      "site_admin" : false,
      "starred_url" : "https://api.github.com/users/hebasto/starred{/owner}{/repo}",
      "subscriptions_url" : "https://api.github.com/users/hebasto/subscriptions",
      "type" : "User",
      "url" : "https://api.github.com/users/hebasto"
   }
}
